<?xml version="1.0"?>

<robot xmlns:xacro="http://www.ros.org/wiki/xacro" name="bumperbot">

    <link name="base_footprint"/>
    <link name="base_link">
        <visual>
            <origin rpy="0 0 0" xyz="0 0 0"/>
            <geometry>
                <mesh filename="package://bumperbot_description/meshes/base_link.STL"/>
            </geometry>
        </visual>
    </link>

    <joint name="base_joint" type="fixed">
        <parent link="base_footprint"/>
        <child link="base_link"/>
        <origin rpy="0 0 0" xyz="0 0 0.033"/>
    </joint>

    <link name="wheel_right_link">
        <visual>
            <origin rpy="1.571 0 0" xyz="0 0 0"/>
            <geometry>
                <mesh filename="package://bumperbot_description/meshes/wheel_right_link.STL"/>
            </geometry>
        </visual>
    </link>

    <joint name="wheel_right_joint" type="continuous">
        <parent link="base_link"/>
        <child link="wheel_right_link"/>
        <axis xyz="0 1 0"/>
        <origin rpy="0 0 0" xyz="0 -0.07 0"/>
    </joint>

    <link name="wheel_left_link">
        <visual>
            <origin rpy="-1.571 0 0" xyz="0 0 0"/>
            <geometry>
                <!-- <mesh filename="package://bumperbot_description/meshes/wheel_left_link.STL"/> -->
                <sphere radius="0.033"/>
            </geometry>
        </visual>
    </link>

    <joint name="wheel_left_joint" type="continuous">
        <parent link="base_link"/>
        <child link="wheel_left_link"/>
        <axis xyz="0 1 0"/>
        <origin rpy="0 0 0" xyz="0 0.07 0"/>
    </joint>

    <link name="caster_front_link">
        <visual>
            <origin rpy="0 0 0" xyz="0 0 0"/>
            <geometry>
                <mesh filename="package://bumperbot_description/meshes/caster_front_link.STL"/>
            </geometry>
        </visual>
    </link>

    <joint name="caster_front_joint" type="fixed">
        <parent link="base_link"/>
        <child link="caster_front_link"/>
        <origin rpy="0 0 0" xyz="0.04755 0 -0.0275"/>
    </joint>

    <link name="caster_rear_link">
        <visual>
            <origin rpy="0 0 0" xyz="0 0 0"/>
            <geometry>
                <mesh filename="package://bumperbot_description/meshes/caster_rear_link.STL"/>
            </geometry>
        </visual>
    </link>

    <joint name="caster_rear_joint" type="fixed">
        <parent link="base_link"/>
        <child link="caster_rear_link"/>
        <origin rpy="0 0 0" xyz="-0.04755 0 -0.0275"/>
    </joint>

    <link name="can_link">
        <visual>
            <origin xyz="-0.03 0.03 0.0" rpy="1.571 0.0 0.0"/>
            <geometry>
                <mesh filename="package://bumperbot_description/meshes/can.STL"/>
            </geometry>
        </visual>
    </link>

    <joint name="can_joint" type="fixed">
        <parent link="base_link"/>
        <child link="can_link"/>
        <origin rpy="0 0 0" xyz="0 0 0.078"/>
    </joint>

</robot>